Workbook

Sheet Léeme
A1: Anexo A — Cálculos del trabajo integrador (Analítica para Negocios, PP7, UNRC)
A3: Observatorio de la Economía del Cuidado — CDMX. Programa evaluado: Red de Cuidado a Domicilio «Manos que Cuidan» (escenario simulado).
A5: Hojas:
A6: Supuestos — todos los supuestos con su fuente. Cambia las celdas azules; las amarillas son las variables por escenario.
A7: Flujo Pesimista / Realista / Optimista — flujo mensual de 60 meses e indicadores (VAN, TIR, payback, punto de equilibrio, capital).
A8: Escenarios — tabla comparativa y valor esperado del VAN.
A9: Pronóstico oferta — serie semestral del DENUE 2016-2026, backtesting e intervalos del pronóstico.
A10: Modelo ENUT — coeficientes, calculadora por AGEB y métricas de validación del modelo de horas de cuidado.
A11: Riesgos — matriz de riesgos con mitigación.
A13: Colores: azul = dato o supuesto editable · negro = fórmula · verde = vínculo a otra hoja · relleno amarillo = supuesto clave.
A14: Unidades: pesos constantes de 2026; tasas reales. Negativos entre paréntesis.
A16: Se genera con notebooks/anexo_excel.py desde el notebook 03; las reglas son las de backend/observatorio/factibilidad.py.
... A24: Supuesto clave

Sheet Supuestos
A1: Supuestos del modelo financiero — Red de Cuidado a Domicilio «Manos que Cuidan» (escenario simulado)
A2: Pesos constantes de 2026. Celdas en azul: supuestos que se pueden cambiar. Relleno amarillo: variables clave por escenario.
A4: Variable que cambia por escenario | B4: Unidad | C4: Pesimista | D4: Realista | E4: Optimista | F4: Fuente o justificación
A5: Adopción en estado estable | B5: % de hogares con necesidad de cuidado | C5: 0.01 | D5: 0.02 | E5: 0.032 | F5: Anclada en la ENASIC 2022 (nacional): 3.2 % de las cuidadoras buscó un servicio formal en el último año; es el techo del escenario optimista.
A6: Horas contratadas por familia | B6: horas por semana | C6: 6 | D6: 8 | E6: 10 | F6: ENUT 2024: las mujeres de la CDMX que cuidan dedican 12.2 h a la semana; el servicio cubre la mitad o algo más.
A7: Subsidio público por hora | B7: pesos por hora | C7: 20 | D7: 40 | E7: 40 | F7: Supuesto de convenio con el Sistema Público de Cuidados de la CDMX (ley promulgada el 2 de julio de 2026). Sin convenio no hay subsidio.
A8: Meses para llegar al estado estable | B8: meses | C8: 24 | D8: 18 | E8: 12
A9: Probabilidad asignada | B9: % | C9: 0.3 | D9: 0.5 | E9: 0.2 | F9: Subjetiva y cargada hacia abajo: no hay historia del servicio y el subsidio depende de un convenio que no existe.
A10: Suma de probabilidades (debe ser 100 %) | C10: =SUM(C9:E9) -> 1
A12: Parámetro común | B12: Unidad | C12: Valor | F12: Fuente o justificación
A13: Hogares con necesidad de cuidado en la zona | B13: hogares | C13: 9415 | F13: Censo 2020 (25 AGEB de Iztapalapa sin respaldo) y ENUT 2024 (1.206 personas con necesidad de cuidado por hogar con necesidad).
A14: Copago de la familia | B14: $ por hora | C14: 60 | F14: Tarifa social, por debajo del mercado (≈ $142/h de una cuidadora de tiempo completo a $25,000 al mes en la CDMX).
A15: Pago bruto a la cuidadora | B15: $ por hora | C15: 55 | F15: 1.28 veces el salario mínimo profesional de las trabajadoras del hogar 2026 ($342.47 diarios, $42.81 por hora en jornada de 8 h).
A16: Prestaciones y seguridad social sobre el pago | B16: % | C16: 0.3 | F16: Seguridad social obligatoria del trabajo del hogar, aguinaldo y vacaciones.
A17: Seguro por hora, insumos y traslados | B17: $ por hora | C17: 3
A18: Jornada de una cuidadora de la red | B18: horas por semana | C18: 30
A19: Rotación mensual de cuidadoras | B19: % | C19: 0.03
A20: Capacitación y verificación por cuidadora nueva | B20: $ | C20: 3500
A21: Familias por trabajadora social | B21: familias | C21: 80
A22: Familias del piloto | B22: familias | C22: 15 | F22: Incidente crítico del PP: piloto de 2 colonias, 15 familias y 6 cuidadoras.
A23: Cuidadoras del piloto | B23: cuidadoras | C23: 6
A24: Duración del piloto | B24: meses | C24: 6
A25: Coordinadora del programa (con 35 % de carga social) | B25: $ al mes | C25: 29700
A26: Trabajadora social (con 35 % de carga social) | B26: $ al mes | C26: 24300
A27: Plataforma: hospedaje, mensajería y mantenimiento | B27: $ al mes | C27: 6000
A28: Póliza de responsabilidad civil | B28: $ al mes | C28: 3000
A29: Trabajo comunitario y difusión | B29: $ al mes | C29: 4000
A30: Contabilidad y facturación | B30: $ al mes | C30: 6000
A31: Inversión: adaptar la plataforma de vinculación | B31: $ | C31: 120000
A32: Inversión: protección de datos (LFPDPPP) | B32: $ | C32: 35000
A33: Inversión: equipamiento (kits, botiquines, teléfonos) | B33: $ | C33: 30000
A34: Inversión: lanzamiento en las colonias | B34: $ | C34: 20000
A35: Tasa de descuento real anual | B35: % | C35: 0.1 | F35: Tasa social de descuento de 10 % real (SHCP, Unidad de Inversiones, 2022).
A36: Colchón para imprevistos | B36: % | C36: 0.1
A37: Mes de revisión (decisión por etapas) | B37: mes | C37: 12
A38: Umbral para continuar (fracción de familias del punto de equilibrio) | B38: % | C38: 0.5
A39: Costo de cierre, en meses de costos fijos | B39: meses | C39: 2
A41: Derivado (fórmula) | B41: Unidad | C41: Valor | F41: Cómo se calcula
A42: Semanas por mes | B42: semanas | C42: =52/12 -> 4.3333333 | F42: 52 semanas ÷ 12 meses
A43: Costo variable por hora | B43: $ por hora | C43: =$C$15*(1+$C$16)+$C$17 -> 74.5 | F43: Pago × (1 + prestaciones) + insumos
...

Sheet Flujo Pesimista
A1: Flujo mensual — escenario pesimista (pesos de 2026)
A2: Todas las celdas son fórmulas que leen la hoja «Supuestos» (texto verde: vínculo). Mes 0 = inversión inicial.
U3: Indicador | V3: Valor
U4: Escenario | V4: Pesimista
A5: Mes | B5: Familias | C5: Horas por semana | D5: Horas al mes | E5: Cuidadoras | F5: Cuidadoras nuevas (incluye rotación) | G5: Trabajadoras sociales | H5: Ingresos ($) | I5: Costo variable ($) | J5: Costos fijos ($) | K5: Capacitación ($) | L5: Inversión ($) | M5: Flujo neto ($) | N5: Flujo acumulado ($) | O5: Factor de descuento | P5: Flujo descontado ($) | Q5: Acumulado descontado ($) | R5: ¿Recuperado? | S5: ¿Recuperado (descontado)? | U5: Tarifa por hora (copago + subsidio) | V5: =Supuestos!$C$14+Supuestos!$C$7 -> 80
A6: 0 | B6: =IF(A6=0,0,IF(A6<=Supuestos!$C$24,Supuestos!$C$22,IF(A6>=Supuestos!$C$8,$V$7,Supuestos!$C$22+($V$7-Supuestos!$C$22)*(A6-Supuestos!$C$24)/(Supuestos!$C$8-Supuestos!$C$24)))) -> 0 | C6: =B6*Supuestos!$C$6 -> 0 | D6: =C6*Supuestos!$C$42 -> 0 | E6: =IF(A6=0,0,MAX(Supuestos!$C$23,ROUNDUP(C6/Supuestos!$C$18,0))) -> 0 | F6: 0 | G6: =IF(A6=0,0,MAX(1,ROUNDUP(B6/Supuestos!$C$21,0))) -> 0 | H6: =D6*(Supuestos!$C$14+Supuestos!$C$7) -> 0 | I6: =D6*Supuestos!$C$43 -> 0 | J6: =IF(A6=0,0,Supuestos!$C$44+G6*Supuestos!$C$26) -> 0 | K6: =F6*Supuestos!$C$20 -> 0 | L6: =IF(A6=0,Supuestos!$C$45,0) -> 226000 | M6: =IF(A6=0,-L6,H6-I6-J6-K6) -> -226000 | N6: =M6 -> -226000 | O6: =1/(1+Supuestos!$C$46)^A6 -> 1 | P6: =M6*O6 -> -226000 | Q6: =P6 -> -226000 | R6: =IF(AND(A6>0,N6>=0),1,0) -> 0 | S6: =IF(AND(A6>0,Q6>=0),1,0) -> 0 | U6: Margen por hora | V6: =V5-Supuestos!$C$43 -> 5.5
A7: 1 | B7: =IF(A7=0,0,IF(A7<=Supuestos!$C$24,Supuestos!$C$22,IF(A7>=Supuestos!$C$8,$V$7,Supuestos!$C$22+($V$7-Supuestos!$C$22)*(A7-Supuestos!$C$24)/(Supuestos!$C$8-Supuestos!$C$24)))) -> 15 | C7: =B7*Supuestos!$C$6 -> 90 | D7: =C7*Supuestos!$C$42 -> 390 | E7: =IF(A7=0,0,MAX(Supuestos!$C$23,ROUNDUP(C7/Supuestos!$C$18,0))) -> 6 | F7: =MAX(0,E7-IF(A6=0,Supuestos!$C$23,E6))+Supuestos!$C$19*E7 -> 0.18 | G7: =IF(A7=0,0,MAX(1,ROUNDUP(B7/Supuestos!$C$21,0))) -> 1 | H7: =D7*(Supuestos!$C$14+Supuestos!$C$7) -> 31200 | I7: =D7*Supuestos!$C$43 -> 29055 | J7: =IF(A7=0,0,Supuestos!$C$44+G7*Supuestos!$C$26) -> 73000 | K7: =F7*Supuestos!$C$20 -> 630 | L7: =IF(A7=0,Supuestos!$C$45,0) -> 0 | M7: =IF(A7=0,-L7,H7-I7-J7-K7) -> -71485 | N7: =N6+M7 -> -297485 | O7: =1/(1+Supuestos!$C$46)^A7 -> 0.99208894 | P7: =M7*O7 -> -70919.478 | Q7: =Q6+P7 -> -296919.48 | R7: =IF(AND(A7>0,N7>=0),1,0) -> 0 | S7: =IF(AND(A7>0,Q7>=0),1,0) -> 0 | U7: Familias objetivo (estado estable) | V7: =MAX(Supuestos!$C$13*Supuestos!$C$5,Supuestos!$C$22) -> 94.15
A8: 2 | B8: =IF(A8=0,0,IF(A8<=Supuestos!$C$24,Supuestos!$C$22,IF(A8>=Supuestos!$C$8,$V$7,Supuestos!$C$22+($V$7-Supuestos!$C$22)*(A8-Supuestos!$C$24)/(Supuestos!$C$8-Supuestos!$C$24)))) -> 15 | C8: =B8*Supuestos!$C$6 -> 90 | D8: =C8*Supuestos!$C$42 -> 390 | E8: =IF(A8=0,0,MAX(Supuestos!$C$23,ROUNDUP(C8/Supuestos!$C$18,0))) -> 6 | F8: =MAX(0,E8-IF(A7=0,Supuestos!$C$23,E7))+Supuestos!$C$19*E8 -> 0.18 | G8: =IF(A8=0,0,MAX(1,ROUNDUP(B8/Supuestos!$C$21,0))) -> 1 | H8: =D8*(Supuestos!$C$14+Supuestos!$C$7) -> 31200 | I8: =D8*Supuestos!$C$43 -> 29055 | J8: =IF(A8=0,0,Supuestos!$C$44+G8*Supuestos!$C$26) -> 73000 | K8: =F8*Supuestos!$C$20 -> 630 | L8: =IF(A8=0,Supuestos!$C$45,0) -> 0 | M8: =IF(A8=0,-L8,H8-I8-J8-K8) -> -71485 | N8: =N7+M8 -> -368970 | O8: =1/(1+Supuestos!$C$46)^A8 -> 0.98424047 | P8: =M8*O8 -> -70358.43 | Q8: =Q7+P8 -> -367277.91 | R8: =IF(AND(A8>0,N8>=0),1,0) -> 0 | S8: =IF(AND(A8>0,Q8>=0),1,0) -> 0 | U8: VAN a la tasa de descuento | V8: =SUM(P6:P66) -> -4031953.4
A9: 3 | B9: =IF(A9=0,0,IF(A9<=Supuestos!$C$24,Supuestos!$C$22,IF(A9>=Supuestos!$C$8,$V$7,Supuestos!$C$22+($V$7-Supuestos!$C$22)*(A9-Supuestos!$C$24)/(Supuestos!$C$8-Supuestos!$C$24)))) -> 15 | C9: =B9*Supuestos!$C$6 -> 90 | D9: =C9*Supuestos!$C$42 -> 390 | E9: =IF(A9=0,0,MAX(Supuestos!$C$23,ROUNDUP(C9/Supuestos!$C$18,0))) -> 6 | F9: =MAX(0,E9-IF(A8=0,Supuestos!$C$23,E8))+Supuestos!$C$19*E9 -> 0.18 | G9: =IF(A9=0,0,MAX(1,ROUNDUP(B9/Supuestos!$C$21,0))) -> 1 | H9: =D9*(Supuestos!$C$14+Supuestos!$C$7) -> 31200 | I9: =D9*Supuestos!$C$43 -> 29055 | J9: =IF(A9=0,0,Supuestos!$C$44+G9*Supuestos!$C$26) -> 73000 | K9: =F9*Supuestos!$C$20 -> 630 | L9: =IF(A9=0,Supuestos!$C$45,0) -> 0 | M9: =IF(A9=0,-L9,H9-I9-J9-K9) -> -71485 | N9: =N8+M9 -> -440455 | O9: =1/(1+Supuestos!$C$46)^A9 -> 0.97645409 | P9: =M9*O9 -> -69801.821 | Q9: =Q8+P9 -> -437079.73 | R9: =IF(AND(A9>0,N9>=0),1,0) -> 0 | S9: =IF(AND(A9>0,Q9>=0),1,0) -> 0 | U9: TIR mensual | V9: =IFERROR(IRR(M6:M66,0.02),"No existe") -> No existe
A10: 4 | B10: =IF(A10=0,0,IF(A10<=Supuestos!$C$24,Supuestos!$C$22,IF(A10>=Supuestos!$C$8,$V$7,Supuestos!$C$22+($V$7-Supuestos!$C$22)*(A10-Supuestos!$C$24)/(Supuestos!$C$8-Supuestos!$C$24)))) -> 15 | C10: =B10*Supuestos!$C$6 -> 90 | D10: =C10*Supuestos!$C$42 -> 390 | E10: =IF(A10=0,0,MAX(Supuestos!$C$23,ROUNDUP(C10/Supuestos!$C$18,0))) -> 6 | F10: =MAX(0,E10-IF(A9=0,Supuestos!$C$23,E9))+Supuestos!$C$19*E10 -> 0.18 | G10: =IF(A10=0,0,MAX(1,ROUNDUP(B10/Supuestos!$C$21,0))) -> 1 | H10: =D10*(Supuestos!$C$14+Supuestos!$C$7) -> 31200 | I10: =D10*Supuestos!$C$43 -> 29055 | J10: =IF(A10=0,0,Supuestos!$C$44+G10*Supuestos!$C$26) -> 73000 | K10: =F10*Supuestos!$C$20 -> 630 | L10: =IF(A10=0,Supuestos!$C$45,0) -> 0 | M10: =IF(A10=0,-L10,H10-I10-J10-K10) -> -71485 | N10: =N9+M10 -> -511940 | O10: =1/(1+Supuestos!$C$46)^A10 -> 0.96872931 | P10: =M10*O10 -> -69249.614 | Q10: =Q9+P10 -> -506329.34 | R10: =IF(AND(A10>0,N10>=0),1,0) -> 0 | S10: =IF(AND(A10>0,Q10>=0),1,0) -> 0 | U10: TIR anual equivalente | V10: =IFERROR((1+V9)^12-1,"No existe") -> No existe
A11: 5 | B11: =IF(A11=0,0,IF(A11<=Supuestos!$C$24,Supuestos!$C$22,IF(A11>=Supuestos!$C$8,$V$7,Supuestos!$C$22+($V$7-Supuestos!$C$22)*(A11-Supuestos!$C$24)/(Supuestos!$C$8-Supuestos!$C$24)))) -> 15 | C11: =B11*Supuestos!$C$6 -> 90 | D11: =C11*Supuestos!$C$42 -> 390 | E11: =IF(A11=0,0,MAX(Supuestos!$C$23,ROUNDUP(C11/Supuestos!$C$18,0))) -> 6 | F11: =MAX(0,E11-IF(A10=0,Supuestos!$C$23,E10))+Supuestos!$C$19*E11 -> 0.18 | G11: =IF(A11=0,0,MAX(1,ROUNDUP(B11/Supuestos!$C$21,0))) -> 1 | H11: =D11*(Supuestos!$C$14+Supuestos!$C$7) -> 31200 | I11: =D11*Supuestos!$C$43 -> 29055 | J11: =IF(A11=0,0,Supuestos!$C$44+G11*Supuestos!$C$26) -> 73000 | K11: =F11*Supuestos!$C$20 -> 630 | L11: =IF(A11=0,Supuestos!$C$45,0) -> 0 | M11: =IF(A11=0,-L11,H11-I11-J11-K11) -> -71485 | N11: =N10+M11 -> -583425 | O11: =1/(1+Supuestos!$C$46)^A11 -> 0.96106563 | P11: =M11*O11 -> -68701.777 | Q11: =Q10+P11 -> -575031.12 | R11: =IF(AND(A11>0,N11>=0),1,0) -> 0 | S11: =IF(AND(A11>0,Q11>=0),1,0) -> 0 | U11: Payback (meses) | V11: =IFERROR(INDEX(A6:A66,MATCH(1,R6:R66,0)),"No se recupera") -> No se recupera
A12: 6 | B12: =IF(A12=0,0,IF(A12<=Supuestos!$C$24,Supuestos!$C$22,IF(A12>=Supuestos!$C$8,$V$7,Supuestos!$C$22+($V$7-Supuestos!$C$22)*(A12-Supuestos!$C$24)/(Supuestos!$C$8-Supuestos!$C$24)))) -> 15 | C12: =B12*Supuestos!$C$6 -> 90 | D12: =C12*Supuestos!$C$42 -> 390 | E12: =IF(A12=0,0,MAX(Supuestos!$C$23,ROUNDUP(C12/Supuestos!$C$18,0))) -> 6 | F12: =MAX(0,E12-IF(A11=0,Supuestos!$C$23,E11))+Supuestos!$C$19*E12 -> 0.18 | G12: =IF(A12=0,0,MAX(1,ROUNDUP(B12/Supuestos!$C$21,0))) -> 1 | H12: =D12*(Supuestos!$C$14+Supuestos!$C$7) -> 31200 | I12: =D12*Supuestos!$C$43 -> 29055 | J12: =IF(A12=0,0,Supuestos!$C$44+G12*Supuestos!$C$26) -> 73000 | K12: =F12*Supuestos!$C$20 -> 630 | L12: =IF(A12=0,Supuestos!$C$45,0) -> 0 | M12: =IF(A12=0,-L12,H12-I12-J12-K12) -> -71485 | N12: =N11+M12 -> -654910 | O12: =1/(1+Supuestos!$C$46)^A12 -> 0.95346259 | P12: =M12*O12 -> -68158.273 | Q12: =Q11+P12 -> -643189.39 | R12: =IF(AND(A12>0,N12>=0),1,0) -> 0 | S12: =IF(AND(A12>0,Q12>=0),1,0) -> 0 | U12: Payback descontado (meses) | V12: =IFERROR(INDEX(A6:A66,MATCH(1,S6:S66,0)),"No se recupera") -> No se recupera
A13: 7 | B13: =IF(A13=0,0,IF(A13<=Supuestos!$C$24,Supuestos!$C$22,IF(A13>=Supuestos!$C$8,$V$7,Supuestos!$C$22+($V$7-Supuestos!$C$22)*(A13-Supuestos!$C$24)/(Supuestos!$C$8-Supuestos!$C$24)))) -> 19.397222 | C13: =B13*Supuestos!$C$6 -> 116.38333 | D13: =C13*Supuestos!$C$42 -> 504.32778 | E13: =IF(A13=0,0,MAX(Supuestos!$C$23,ROUNDUP(C13/Supuestos!$C$18,0))) -> 6 | F13: =MAX(0,E13-IF(A12=0,Supuestos!$C$23,E12))+Supuestos!$C$19*E13 -> 0.18 | G13: =IF(A13=0,0,MAX(1,ROUNDUP(B13/Supuestos!$C$21,0))) -> 1 | H13: =D13*(Supuestos!$C$14+Supuestos!$C$7) -> 40346.222 | I13: =D13*Supuestos!$C$43 -> 37572.419 | J13: =IF(A13=0,0,Supuestos!$C$44+G13*Supuestos!$C$26) -> 73000 | K13: =F13*Supuestos!$C$20 -> 630 | L13: =IF(A13=0,Supuestos!$C$45,0) -> 0 | M13: =IF(A13=0,-L13,H13-I13-J13-K13) -> -70856.197 | N13: =N12+M13 -> -725766.2 | O13: =1/(1+Supuestos!$C$46)^A13 -> 0.94591969 | P13: =M13*O13 -> -67024.272 | Q13: =Q12+P13 -> -710213.67 | R13: =IF(AND(A13>0,N13>=0),1,0) -> 0 | S13: =IF(AND(A13>0,Q13>=0),1,0) -> 0 | U13: Costos fijos en estado estable | V13: =J66 -> 97300
A14: 8 | B14: =IF(A14=0,0,IF(A14<=Supuestos!$C$24,Supuestos!$C$22,IF(A14>=Supuestos!$C$8,$V$7,Supuestos!$C$22+($V$7-Supuestos!$C$22)*(A14-Supuestos!$C$24)/(Supuestos!$C$8-Supuestos!$C$24)))) -> 23.794444 | C14: =B14*Supuestos!$C$6 -> 142.76667 | D14: =C14*Supuestos!$C$42 -> 618.65556 | E14: =IF(A14=0,0,MAX(Supuestos!$C$23,ROUNDUP(C14/Supuestos!$C$18,0))) -> 6 | F14: =MAX(0,E14-IF(A13=0,Supuestos!$C$23,E13))+Supuestos!$C$19*E14 -> 0.18 | G14: =IF(A14=0,0,MAX(1,ROUNDUP(B14/Supuestos!$C$21,0))) -> 1 | H14: =D14*(Supuestos!$C$14+Supuestos!$C$7) -> 49492.444 | I14: =D14*Supuestos!$C$43 -> 46089.839 | J14: =IF(A14=0,0,Supuestos!$C$44+G14*Supuestos!$C$26) -> 73000 | K14: =F14*Supuestos!$C$20 -> 630 | L14: =IF(A14=0,Supuestos!$C$45,0) -> 0 | M14: =IF(A14=0,-L14,H14-I14-J14-K14) -> -70227.394 | N14: =N13+M14 -> -795993.59 | O14: =1/(1+Supuestos!$C$46)^A14 -> 0.93843647 | P14: =M14*O14 -> -65903.948 | Q14: =Q13+P14 -> -776117.61 | R14: =IF(AND(A14>0,N14>=0),1,0) -> 0 | S14: =IF(AND(A14>0,Q14>=0),1,0) -> 0 | U14: Punto de equilibrio (horas al mes) | V14: =IF(V6>0,V13/V6,"No existe") -> 17690.909
A15: 9 | B15: =IF(A15=0,0,IF(A15<=Supuestos!$C$24,Supuestos!$C$22,IF(A15>=Supuestos!$C$8,$V$7,Supuestos!$C$22+($V$7-Supuestos!$C$22)*(A15-Supuestos!$C$24)/(Supuestos!$C$8-Supuestos!$C$24)))) -> 28.191667 | C15: =B15*Supuestos!$C$6 -> 169.15 | D15: =C15*Supuestos!$C$42 -> 732.98333 | E15: =IF(A15=0,0,MAX(Supuestos!$C$23,ROUNDUP(C15/Supuestos!$C$18,0))) -> 6 | F15: =MAX(0,E15-IF(A14=0,Supuestos!$C$23,E14))+Supuestos!$C$19*E15 -> 0.18 | G15: =IF(A15=0,0,MAX(1,ROUNDUP(B15/Supuestos!$C$21,0))) -> 1 | H15: =D15*(Supuestos!$C$14+Supuestos!$C$7) -> 58638.667 | I15: =D15*Supuestos!$C$43 -> 54607.258 | J15: =IF(A15=0,0,Supuestos!$C$44+G15*Supuestos!$C$26) -> 73000 | K15: =F15*Supuestos!$C$20 -> 630 | L15: =IF(A15=0,Supuestos!$C$45,0) -> 0 | M15: =IF(A15=0,-L15,H15-I15-J15-K15) -> -69598.592 | N15: =N14+M15 -> -865592.18 | O15: =1/(1+Supuestos!$C$46)^A15 -> 0.93101244 | P15: =M15*O15 -> -64797.155 | Q15: =Q14+P15 -> -840914.77 | R15: =IF(AND(A15>0,N15>=0),1,0) -> 0 | S15: =IF(AND(A15>0,Q15>=0),1,0) -> 0 | U15: Punto de equilibrio (familias) | V15: =IF(V6>0,V14/Supuestos!$C$42/Supuestos!$C$6,"No existe") -> 680.41958
A16: 10 | B16: =IF(A16=0,0,IF(A16<=Supuestos!$C$24,Supuestos!$C$22,IF(A16>=Supuestos!$C$8,$V$7,Supuestos!$C$22+($V$7-Supuestos!$C$22)*(A16-Supuestos!$C$24)/(Supuestos!$C$8-Supuestos!$C$24)))) -> 32.588889 | C16: =B16*Supuestos!$C$6 -> 195.53333 | D16: =C16*Supuestos!$C$42 -> 847.31111 | E16: =IF(A16=0,0,MAX(Supuestos!$C$23,ROUNDUP(C16/Supuestos!$C$18,0))) -> 7 | F16: =MAX(0,E16-IF(A15=0,Supuestos!$C$23,E15))+Supuestos!$C$19*E16 -> 1.21 | G16: =IF(A16=0,0,MAX(1,ROUNDUP(B16/Supuestos!$C$21,0))) -> 1 | H16: =D16*(Supuestos!$C$14+Supuestos!$C$7) -> 67784.889 | I16: =D16*Supuestos!$C$43 -> 63124.678 | J16: =IF(A16=0,0,Supuestos!$C$44+G16*Supuestos!$C$26) -> 73000 | K16: =F16*Supuestos!$C$20 -> 4235 | L16: =IF(A16=0,Supuestos!$C$45,0) -> 0 | M16: =IF(A16=0,-L16,H16-I16-J16-K16) -> -72574.789 | N16: =N15+M16 -> -938166.97 | O16: =1/(1+Supuestos!$C$46)^A16 -> 0.92364715 | P16: =M16*O16 -> -67033.497 | Q16: =Q15+P16 -> -907948.27 | R16: =IF(AND(A16>0,N16>=0),1,0) -> 0 | S16: =IF(AND(A16>0,Q16>=0),1,0) -> 0 | U16: Utilidad neta acumulada (60 meses) | V16: =N66 -> -5078090.5
A17: 11 | B17: =IF(A17=0,0,IF(A17<=Supuestos!$C$24,Supuestos!$C$22,IF(A17>=Supuestos!$C$8,$V$7,Supuestos!$C$22+($V$7-Supuestos!$C$22)*(A17-Supuestos!$C$24)/(Supuestos!$C$8-Supuestos!$C$24)))) -> 36.986111 | C17: =B17*Supuestos!$C$6 -> 221.91667 | D17: =C17*Supuestos!$C$42 -> 961.63889 | E17: =IF(A17=0,0,MAX(Supuestos!$C$23,ROUNDUP(C17/Supuestos!$C$18,0))) -> 8 | F17: =MAX(0,E17-IF(A16=0,Supuestos!$C$23,E16))+Supuestos!$C$19*E17 -> 1.24 | G17: =IF(A17=0,0,MAX(1,ROUNDUP(B17/Supuestos!$C$21,0))) -> 1 | H17: =D17*(Supuestos!$C$14+Supuestos!$C$7) -> 76931.111 | I17: =D17*Supuestos!$C$43 -> 71642.097 | J17: =IF(A17=0,0,Supuestos!$C$44+G17*Supuestos!$C$26) -> 73000 | K17: =F17*Supuestos!$C$20 -> 4340 | L17: =IF(A17=0,Supuestos!$C$45,0) -> 0 | M17: =IF(A17=0,-L17,H17-I17-J17-K17) -> -72050.986 | N17: =N16+M17 -> -1010218 | O17: =1/(1+Supuestos!$C$46)^A17 -> 0.91634013 | P17: =M17*O17 -> -66023.21 | Q17: =Q16+P17 -> -973971.48 | R17: =IF(AND(A17>0,N17>=0),1,0) -> 0 | S17: =IF(AND(A17>0,Q17>=0),1,0) -> 0 | U17: Inversión inicial | V17: =L6 -> 226000
A18: 12 | B18: =IF(A18=0,0,IF(A18<=Supuestos!$C$24,Supuestos!$C$22,IF(A18>=Supuestos!$C$8,$V$7,Supuestos!$C$22+($V$7-Supuestos!$C$22)*(A18-Supuestos!$C$24)/(Supuestos!$C$8-Supuestos!$C$24)))) -> 41.383333 | C18: =B18*Supuestos!$C$6 -> 248.3 | D18: =C18*Supuestos!$C$42 -> 1075.9667 | E18: =IF(A18=0,0,MAX(Supuestos!$C$23,ROUNDUP(C18/Supuestos!$C$18,0))) -> 9 | F18: =MAX(0,E18-IF(A17=0,Supuestos!$C$23,E17))+Supuestos!$C$19*E18 -> 1.27 | G18: =IF(A18=0,0,MAX(1,ROUNDUP(B18/Supuestos!$C$21,0))) -> 1 | H18: =D18*(Supuestos!$C$14+Supuestos!$C$7) -> 86077.333 | I18: =D18*Supuestos!$C$43 -> 80159.517 | J18: =IF(A18=0,0,Supuestos!$C$44+G18*Supuestos!$C$26) -> 73000 | K18: =F18*Supuestos!$C$20 -> 4445 | L18: =IF(A18=0,Supuestos!$C$45,0) -> 0 | M18: =IF(A18=0,-L18,H18-I18-J18-K18) -> -71527.183 | N18: =N17+M18 -> -1081745.1 | O18: =1/(1+Supuestos!$C$46)^A18 -> 0.90909091 | P18: =M18*O18 -> -65024.712 | Q18: =Q17+P18 -> -1038996.2 | R18: =IF(AND(A18>0,N18>=0),1,0) -> 0 | S18: =IF(AND(A18>0,Q18>=0),1,0) -> 0 | U18: Capital de operación (3 meses) | V18: =3*(J7+I7) -> 306165
A19: 13 | B19: =IF(A19=0,0,IF(A19<=Supuestos!$C$24,Supuestos!$C$22,IF(A19>=Supuestos!$C$8,$V$7,Supuestos!$C$22+($V$7-Supuestos!$C$22)*(A19-Supuestos!$C$24)/(Supuestos!$C$8-Supuestos!$C$24)))) -> 45.780556 | C19: =B19*Supuestos!$C$6 -> 274.68333 | D19: =C19*Supuestos!$C$42 -> 1190.2944 | E19: =IF(A19=0,0,MAX(Supuestos!$C$23,ROUNDUP(C19/Supuestos!$C$18,0))) -> 10 | F19: =MAX(0,E19-IF(A18=0,Supuestos!$C$23,E18))+Supuestos!$C$19*E19 -> 1.3 | G19: =IF(A19=0,0,MAX(1,ROUNDUP(B19/Supuestos!$C$21,0))) -> 1 | H19: =D19*(Supuestos!$C$14+Supuestos!$C$7) -> 95223.556 | I19: =D19*Supuestos!$C$43 -> 88676.936 | J19: =IF(A19=0,0,Supuestos!$C$44+G19*Supuestos!$C$26) -> 73000 | K19: =F19*Supuestos!$C$20 -> 4550 | L19: =IF(A19=0,Supuestos!$C$45,0) -> 0 | M19: =IF(A19=0,-L19,H19-I19-J19-K19) -> -71003.381 | N19: =N18+M19 -> -1152748.5 | O19: =1/(1+Supuestos!$C$46)^A19 -> 0.90189904 | P19: =M19*O19 -> -64037.881 | Q19: =Q18+P19 -> -1103034.1 | R19: =IF(AND(A19>0,N19>=0),1,0) -> 0 | S19: =IF(AND(A19>0,Q19>=0),1,0) -> 0 | U19: Colchón para imprevistos | V19: =Supuestos!$C$36*(V17+V18) -> 53216.5
A20: 14 | B20: =IF(A20=0,0,IF(A20<=Supuestos!$C$24,Supuestos!$C$22,IF(A20>=Supuestos!$C$8,$V$7,Supuestos!$C$22+($V$7-Supuestos!$C$22)*(A20-Supuestos!$C$24)/(Supuestos!$C$8-Supuestos!$C$24)))) -> 50.177778 | C20: =B20*Supuestos!$C$6 -> 301.06667 | D20: =C20*Supuestos!$C$42 -> 1304.6222 | E20: =IF(A20=0,0,MAX(Supuestos!$C$23,ROUNDUP(C20/Supuestos!$C$18,0))) -> 11 | F20: =MAX(0,E20-IF(A19=0,Supuestos!$C$23,E19))+Supuestos!$C$19*E20 -> 1.33 | G20: =IF(A20=0,0,MAX(1,ROUNDUP(B20/Supuestos!$C$21,0))) -> 1 | H20: =D20*(Supuestos!$C$14+Supuestos!$C$7) -> 104369.78 | I20: =D20*Supuestos!$C$43 -> 97194.356 | J20: =IF(A20=0,0,Supuestos!$C$44+G20*Supuestos!$C$26) -> 73000 | K20: =F20*Supuestos!$C$20 -> 4655 | L20: =IF(A20=0,Supuestos!$C$45,0) -> 0 | M20: =IF(A20=0,-L20,H20-I20-J20-K20) -> -70479.578 | N20: =N19+M20 -> -1223228.1 | O20: =1/(1+Supuestos!$C$46)^A20 -> 0.89476407 | P20: =M20*O20 -> -63062.594 | Q20: =Q19+P20 -> -1166096.7 | R20: =IF(AND(A20>0,N20>=0),1,0) -> 0 | S20: =IF(AND(A20>0,Q20>=0),1,0) -> 0 | U20: Requerimiento total de capital | V20: =V17+V18+V19 -> 585381.5
A21: 15 | B21: =IF(A21=0,0,IF(A21<=Supuestos!$C$24,Supuestos!$C$22,IF(A21>=Supuestos!$C$8,$V$7,Supuestos!$C$22+($V$7-Supuestos!$C$22)*(A21-Supuestos!$C$24)/(Supuestos!$C$8-Supuestos!$C$24)))) -> 54.575 | C21: =B21*Supuestos!$C$6 -> 327.45 | D21: =C21*Supuestos!$C$42 -> 1418.95 | E21: =IF(A21=0,0,MAX(Supuestos!$C$23,ROUNDUP(C21/Supuestos!$C$18,0))) -> 11 | F21: =MAX(0,E21-IF(A20=0,Supuestos!$C$23,E20))+Supuestos!$C$19*E21 -> 0.33 | G21: =IF(A21=0,0,MAX(1,ROUNDUP(B21/Supuestos!$C$21,0))) -> 1 | H21: =D21*(Supuestos!$C$14+Supuestos!$C$7) -> 113516 | I21: =D21*Supuestos!$C$43 -> 105711.77 | J21: =IF(A21=0,0,Supuestos!$C$44+G21*Supuestos!$C$26) -> 73000 | K21: =F21*Supuestos!$C$20 -> 1155 | L21: =IF(A21=0,Supuestos!$C$45,0) -> 0 | M21: =IF(A21=0,-L21,H21-I21-J21-K21) -> -66350.775 | N21: =N20+M21 -> -1289578.9 | O21: =1/(1+Supuestos!$C$46)^A21 -> 0.88768554 | P21: =M21*O21 -> -58898.623 | Q21: =Q20+P21 -> -1224995.3 | R21: =IF(AND(A21>0,N21>=0),1,0) -> 0 | S21: =IF(AND(A21>0,Q21>=0),1,0) -> 0 | U21: Déficit acumulado máximo | V21: =-MIN(0,MIN(N6:N66)) -> 5078090.5
A22: 16 | B22: =IF(A22=0,0,IF(A22<=Supuestos!$C$24,Supuestos!$C$22,IF(A22>=Supuestos!$C$8,$V$7,Supuestos!$C$22+($V$7-Supuestos!$C$22)*(A22-Supuestos!$C$24)/(Supuestos!$C$8-Supuestos!$C$24)))) -> 58.972222 | C22: =B22*Supuestos!$C$6 -> 353.83333 | D22: =C22*Supuestos!$C$42 -> 1533.2778 | E22: =IF(A22=0,0,MAX(Supuestos!$C$23,ROUNDUP(C22/Supuestos!$C$18,0))) -> 12 | F22: =MAX(0,E22-IF(A21=0,Supuestos!$C$23,E21))+Supuestos!$C$19*E22 -> 1.36 | G22: =IF(A22=0,0,MAX(1,ROUNDUP(B22/Supuestos!$C$21,0))) -> 1 | H22: =D22*(Supuestos!$C$14+Supuestos!$C$7) -> 122662.22 | I22: =D22*Supuestos!$C$43 -> 114229.19 | J22: =IF(A22=0,0,Supuestos!$C$44+G22*Supuestos!$C$26) -> 73000 | K22: =F22*Supuestos!$C$20 -> 4760 | L22: =IF(A22=0,Supuestos!$C$45,0) -> 0 | M22: =IF(A22=0,-L22,H22-I22-J22-K22) -> -69326.972 | N22: =N21+M22 -> -1358905.8 | O22: =1/(1+Supuestos!$C$46)^A22 -> 0.88066301 | P22: =M22*O22 -> -61053.7 | Q22: =Q21+P22 -> -1286049 | R22: =IF(AND(A22>0,N22>=0),1,0) -> 0 | S22: =IF(AND(A22>0,Q22>=0),1,0) -> 0 | U22: Familias en estado estable | V22: =B66 -> 94.15
A23: 17 | B23: =IF(A23=0,0,IF(A23<=Supuestos!$C$24,Supuestos!$C$22,IF(A23>=Supuestos!$C$8,$V$7,Supuestos!$C$22+($V$7-Supuestos!$C$22)*(A23-Supuestos!$C$24)/(Supuestos!$C$8-Supuestos!$C$24)))) -> 63.369444 | C23: =B23*Supuestos!$C$6 -> 380.21667 | D23: =C23*Supuestos!$C$42 -> 1647.6056 | E23: =IF(A23=0,0,MAX(Supuestos!$C$23,ROUNDUP(C23/Supuestos!$C$18,0))) -> 13 | F23: =MAX(0,E23-IF(A22=0,Supuestos!$C$23,E22))+Supuestos!$C$19*E23 -> 1.39 | G23: =IF(A23=0,0,MAX(1,ROUNDUP(B23/Supuestos!$C$21,0))) -> 1 | H23: =D23*(Supuestos!$C$14+Supuestos!$C$7) -> 131808.44 | I23: =D23*Supuestos!$C$43 -> 122746.61 | J23: =IF(A23=0,0,Supuestos!$C$44+G23*Supuestos!$C$26) -> 73000 | K23: =F23*Supuestos!$C$20 -> 4865 | L23: =IF(A23=0,Supuestos!$C$45,0) -> 0 | M23: =IF(A23=0,-L23,H23-I23-J23-K23) -> -68803.169 | N23: =N22+M23 -> -1427709 | O23: =1/(1+Supuestos!$C$46)^A23 -> 0.87369603 | P23: =M23*O23 -> -60113.056 | Q23: =Q22+P23 -> -1346162 | R23: =IF(AND(A23>0,N23>=0),1,0) -> 0 | S23: =IF(AND(A23>0,Q23>=0),1,0) -> 0 | U23: Horas de cuidado al mes en estado estable | V23: =D66 -> 2447.9
A24: 18 | B24: =IF(A24=0,0,IF(A24<=Supuestos!$C$24,Supuestos!$C$22,IF(A24>=Supuestos!$C$8,$V$7,Supuestos!$C$22+($V$7-Supuestos!$C$22)*(A24-Supuestos!$C$24)/(Supuestos!$C$8-Supuestos!$C$24)))) -> 67.766667 | C24: =B24*Supuestos!$C$6 -> 406.6 | D24: =C24*Supuestos!$C$42 -> 1761.9333 | E24: =IF(A24=0,0,MAX(Supuestos!$C$23,ROUNDUP(C24/Supuestos!$C$18,0))) -> 14 | F24: =MAX(0,E24-IF(A23=0,Supuestos!$C$23,E23))+Supuestos!$C$19*E24 -> 1.42 | G24: =IF(A24=0,0,MAX(1,ROUNDUP(B24/Supuestos!$C$21,0))) -> 1 | H24: =D24*(Supuestos!$C$14+Supuestos!$C$7) -> 140954.67 | I24: =D24*Supuestos!$C$43 -> 131264.03 | J24: =IF(A24=0,0,Supuestos!$C$44+G24*Supuestos!$C$26) -> 73000 | K24: =F24*Supuestos!$C$20 -> 4970 | L24: =IF(A24=0,Supuestos!$C$45,0) -> 0 | M24: =IF(A24=0,-L24,H24-I24-J24-K24) -> -68279.367 | N24: =N23+M24 -> -1495988.4 | O24: =1/(1+Supuestos!$C$46)^A24 -> 0.86678417 | P24: =M24*O24 -> -59183.474 | Q24: =Q23+P24 -> -1405345.5 | R24: =IF(AND(A24>0,N24>=0),1,0) -> 0 | S24: =IF(AND(A24>0,Q24>=0),1,0) -> 0 | U24: Cuidadoras empleadas en estado estable | V24: =E66 -> 19
A25: 19 | B25: =IF(A25=0,0,IF(A25<=Supuestos!$C$24,Supuestos!$C$22,IF(A25>=Supuestos!$C$8,$V$7,Supuestos!$C$22+($V$7-Supuestos!$C$22)*(A25-Supuestos!$C$24)/(Supuestos!$C$8-Supuestos!$C$24)))) -> 72.163889 | C25: =B25*Supuestos!$C$6 -> 432.98333 | D25: =C25*Supuestos!$C$42 -> 1876.2611 | E25: =IF(A25=0,0,MAX(Supuestos!$C$23,ROUNDUP(C25/Supuestos!$C$18,0))) -> 15 | F25: =MAX(0,E25-IF(A24=0,Supuestos!$C$23,E24))+Supuestos!$C$19*E25 -> 1.45 | G25: =IF(A25=0,0,MAX(1,ROUNDUP(B25/Supuestos!$C$21,0))) -> 1 | H25: =D25*(Supuestos!$C$14+Supuestos!$C$7) -> 150100.89 | I25: =D25*Supuestos!$C$43 -> 139781.45 | J25: =IF(A25=0,0,Supuestos!$C$44+G25*Supuestos!$C$26) -> 73000 | K25: =F25*Supuestos!$C$20 -> 5075 | L25: =IF(A25=0,Supuestos!$C$45,0) -> 0 | M25: =IF(A25=0,-L25,H25-I25-J25-K25) -> -67755.564 | N25: =N24+M25 -> -1563743.9 | O25: =1/(1+Supuestos!$C$46)^A25 -> 0.85992699 | P25: =M25*O25 -> -58264.838 | Q25: =Q24+P25 -> -1463610.4 | R25: =IF(AND(A25>0,N25>=0),1,0) -> 0 | S25: =IF(AND(A25>0,Q25>=0),1,0) -> 0 | U25: Familias en el mes de revisión | V25: =INDEX(B6:B66,(Supuestos!$C$37+1)) -> 41.383333
A26: 20 | B26: =IF(A26=0,0,IF(A26<=Supuestos!$C$24,Supuestos!$C$22,IF(A26>=Supuestos!$C$8,$V$7,Supuestos!$C$22+($V$7-Supuestos!$C$22)*(A26-Supuestos!$C$24)/(Supuestos!$C$8-Supuestos!$C$24)))) -> 76.561111 | C26: =B26*Supuestos!$C$6 -> 459.36667 | D26: =C26*Supuestos!$C$42 -> 1990.5889 | E26: =IF(A26=0,0,MAX(Supuestos!$C$23,ROUNDUP(C26/Supuestos!$C$18,0))) -> 16 | F26: =MAX(0,E26-IF(A25=0,Supuestos!$C$23,E25))+Supuestos!$C$19*E26 -> 1.48 | G26: =IF(A26=0,0,MAX(1,ROUNDUP(B26/Supuestos!$C$21,0))) -> 1 | H26: =D26*(Supuestos!$C$14+Supuestos!$C$7) -> 159247.11 | I26: =D26*Supuestos!$C$43 -> 148298.87 | J26: =IF(A26=0,0,Supuestos!$C$44+G26*Supuestos!$C$26) -> 73000 | K26: =F26*Supuestos!$C$20 -> 5180 | L26: =IF(A26=0,Supuestos!$C$45,0) -> 0 | M26: =IF(A26=0,-L26,H26-I26-J26-K26) -> -67231.761 | N26: =N25+M26 -> -1630975.7 | O26: =1/(1+Supuestos!$C$46)^A26 -> 0.85312406 | P26: =M26*O26 -> -57357.033 | Q26: =Q25+P26 -> -1520967.4 | R26: =IF(AND(A26>0,N26>=0),1,0) -> 0 | S26: =IF(AND(A26>0,Q26>=0),1,0) -> 0 | U26: ¿Se cierra en la revisión? | V26: =IF(ISNUMBER(V15),IF(V25<Supuestos!$C$38*V15,"Sí","No"),"Sí") -> Sí
A27: 21 | B27: =IF(A27=0,0,IF(A27<=Supuestos!$C$24,Supuestos!$C$22,IF(A27>=Supuestos!$C$8,$V$7,Supuestos!$C$22+($V$7-Supuestos!$C$22)*(A27-Supuestos!$C$24)/(Supuestos!$C$8-Supuestos!$C$24)))) -> 80.958333 | C27: =B27*Supuestos!$C$6 -> 485.75 | D27: =C27*Supuestos!$C$42 -> 2104.9167 | E27: =IF(A27=0,0,MAX(Supuestos!$C$23,ROUNDUP(C27/Supuestos!$C$18,0))) -> 17 | F27: =MAX(0,E27-IF(A26=0,Supuestos!$C$23,E26))+Supuestos!$C$19*E27 -> 1.51 | G27: =IF(A27=0,0,MAX(1,ROUNDUP(B27/Supuestos!$C$21,0))) -> 2 | H27: =D27*(Supuestos!$C$14+Supuestos!$C$7) -> 168393.33 | I27: =D27*Supuestos!$C$43 -> 156816.29 | J27: =IF(A27=0,0,Supuestos!$C$44+G27*Supuestos!$C$26) -> 97300 | K27: =F27*Supuestos!$C$20 -> 5285 | L27: =IF(A27=0,Supuestos!$C$45,0) -> 0 | M27: =IF(A27=0,-L27,H27-I27-J27-K27) -> -91007.958 | N27: =N26+M27 -> -1721983.7 | O27: =1/(1+Supuestos!$C$46)^A27 -> 0.84637495 | P27: =M27*O27 -> -77026.856 | Q27: =Q26+P27 -> -1597994.2 | R27: =IF(AND(A27>0,N27>=0),1,0) -> 0 | S27: =IF(AND(A27>0,Q27>=0),1,0) -> 0 | U27: Costo de cierre | V27: =Supuestos!$C$39*INDEX(J6:J66,(Supuestos!$C$37+1)) -> 146000
A28: 22 | B28: =IF(A28=0,0,IF(A28<=Supuestos!$C$24,Supuestos!$C$22,IF(A28>=Supuestos!$C$8,$V$7,Supuestos!$C$22+($V$7-Supuestos!$C$22)*(A28-Supuestos!$C$24)/(Supuestos!$C$8-Supuestos!$C$24)))) -> 85.355556 | C28: =B28*Supuestos!$C$6 -> 512.13333 | D28: =C28*Supuestos!$C$42 -> 2219.2444 | E28: =IF(A28=0,0,MAX(Supuestos!$C$23,ROUNDUP(C28/Supuestos!$C$18,0))) -> 18 | F28: =MAX(0,E28-IF(A27=0,Supuestos!$C$23,E27))+Supuestos!$C$19*E28 -> 1.54 | G28: =IF(A28=0,0,MAX(1,ROUNDUP(B28/Supuestos!$C$21,0))) -> 2 | H28: =D28*(Supuestos!$C$14+Supuestos!$C$7) -> 177539.56 | I28: =D28*Supuestos!$C$43 -> 165333.71 | J28: =IF(A28=0,0,Supuestos!$C$44+G28*Supuestos!$C$26) -> 97300 | K28: =F28*Supuestos!$C$20 -> 5390 | L28: =IF(A28=0,Supuestos!$C$45,0) -> 0 | M28: =IF(A28=0,-L28,H28-I28-J28-K28) -> -90484.156 | N28: =N27+M28 -> -1812467.8 | O28: =1/(1+Supuestos!$C$46)^A28 -> 0.83967923 | P28: =M28*O28 -> -75977.666 | Q28: =Q27+P28 -> -1673971.9 | R28: =IF(AND(A28>0,N28>=0),1,0) -> 0 | S28: =IF(AND(A28>0,Q28>=0),1,0) -> 0 | U28: VAN con revisión en el mes 12 | V28: =IF(V26="Sí",SUM(P6:INDEX(P6:P66,(Supuestos!$C$37+1)))-V27/(1+Supuestos!$C$46)^(Supuestos!$C$37+1),V8) -> -1170673.4
A29: 23 | B29: =IF(A29=0,0,IF(A29<=Supuestos!$C$24,Supuestos!$C$22,IF(A29>=Supuestos!$C$8,$V$7,Supuestos!$C$22+($V$7-Supuestos!$C$22)*(A29-Supuestos!$C$24)/(Supuestos!$C$8-Supuestos!$C$24)))) -> 89.752778 | C29: =B29*Supuestos!$C$6 -> 538.51667 | D29: =C29*Supuestos!$C$42 -> 2333.5722 | E29: =IF(A29=0,0,MAX(Supuestos!$C$23,ROUNDUP(C29/Supuestos!$C$18,0))) -> 18 | F29: =MAX(0,E29-IF(A28=0,Supuestos!$C$23,E28))+Supuestos!$C$19*E29 -> 0.54 | G29: =IF(A29=0,0,MAX(1,ROUNDUP(B29/Supuestos!$C$21,0))) -> 2 | H29: =D29*(Supuestos!$C$14+Supuestos!$C$7) -> 186685.78 | I29: =D29*Supuestos!$C$43 -> 173851.13 | J29: =IF(A29=0,0,Supuestos!$C$44+G29*Supuestos!$C$26) -> 97300 | K29: =F29*Supuestos!$C$20 -> 1890 | L29: =IF(A29=0,Supuestos!$C$45,0) -> 0 | M29: =IF(A29=0,-L29,H29-I29-J29-K29) -> -86355.353 | N29: =N28+M29 -> -1898823.2 | O29: =1/(1+Supuestos!$C$46)^A29 -> 0.83303648 | P29: =M29*O29 -> -71937.159 | Q29: =Q28+P29 -> -1745909.1 | R29: =IF(AND(A29>0,N29>=0),1,0) -> 0 | S29: =IF(AND(A29>0,Q29>=0),1,0) -> 0 | U29: Utilidad neta con revisión | V29: =IF(V26="Sí",SUM(M6:INDEX(M6:M66,(Supuestos!$C$37+1)))-V27,V16) -> -1227745.1
A30: 24 | B30: =IF(A30=0,0,IF(A30<=Supuestos!$C$24,Supuestos!$C$22,IF(A30>=Supuestos!$C$8,$V$7,Supuestos!$C$22+($V$7-Supuestos!$C$22)*(A30-Supuestos!$C$24)/(Supuestos!$C$8-Supuestos!$C$24)))) -> 94.15 | C30: =B30*Supuestos!$C$6 -> 564.9 | D30: =C30*Supuestos!$C$42 -> 2447.9 | E30: =IF(A30=0,0,MAX(Supuestos!$C$23,ROUNDUP(C30/Supuestos!$C$18,0))) -> 19 | F30: =MAX(0,E30-IF(A29=0,Supuestos!$C$23,E29))+Supuestos!$C$19*E30 -> 1.57 | G30: =IF(A30=0,0,MAX(1,ROUNDUP(B30/Supuestos!$C$21,0))) -> 2 | H30: =D30*(Supuestos!$C$14+Supuestos!$C$7) -> 195832 | I30: =D30*Supuestos!$C$43 -> 182368.55 | J30: =IF(A30=0,0,Supuestos!$C$44+G30*Supuestos!$C$26) -> 97300 | K30: =F30*Supuestos!$C$20 -> 5495 | L30: =IF(A30=0,Supuestos!$C$45,0) -> 0 | M30: =IF(A30=0,-L30,H30-I30-J30-K30) -> -89331.55 | N30: =N29+M30 -> -1988154.7 | O30: =1/(1+Supuestos!$C$46)^A30 -> 0.82644628 | P30: =M30*O30 -> -73827.727 | Q30: =Q29+P30 -> -1819736.8 | R30: =IF(AND(A30>0,N30>=0),1,0) -> 0 | S30: =IF(AND(A30>0,Q30>=0),1,0) -> 0
A31: 25 | B31: =IF(A31=0,0,IF(A31<=Supuestos!$C$24,Supuestos!$C$22,IF(A31>=Supuestos!$C$8,$V$7,Supuestos!$C$22+($V$7-Supuestos!$C$22)*(A31-Supuestos!$C$24)/(Supuestos!$C$8-Supuestos!$C$24)))) -> 94.15 | C31: =B31*Supuestos!$C$6 -> 564.9 | D31: =C31*Supuestos!$C$42 -> 2447.9 | E31: =IF(A31=0,0,MAX(Supuestos!$C$23,ROUNDUP(C31/Supuestos!$C$18,0))) -> 19 | F31: =MAX(0,E31-IF(A30=0,Supuestos!$C$23,E30))+Supuestos!$C$19*E31 -> 0.57 | G31: =IF(A31=0,0,MAX(1,ROUNDUP(B31/Supuestos!$C$21,0))) -> 2 | H31: =D31*(Supuestos!$C$14+Supuestos!$C$7) -> 195832 | I31: =D31*Supuestos!$C$43 -> 182368.55 | J31: =IF(A31=0,0,Supuestos!$C$44+G31*Supuestos!$C$26) -> 97300 | K31: =F31*Supuestos!$C$20 -> 1995 | L31: =IF(A31=0,Supuestos!$C$45,0) -> 0 | M31: =IF(A31=0,-L31,H31-I31-J31-K31) -> -85831.55 | N31: =N30+M31 -> -2073986.3 | O31: =1/(1+Supuestos!$C$46)^A31 -> 0.81990822 | P31: =M31*O31 -> -70373.993 | Q31: =Q30+P31 -> -1890110.8 | R31: =IF(AND(A31>0,N31>=0),1,0) -> 0 | S31: =IF(AND(A31>0,Q31>=0),1,0) -> 0
A32: 26 | B32: =IF(A32=0,0,IF(A32<=Supuestos!$C$24,Supuestos!$C$22,IF(A32>=Supuestos!$C$8,$V$7,Supuestos!$C$22+($V$7-Supuestos!$C$22)*(A32-Supuestos!$C$24)/(Supuestos!$C$8-Supuestos!$C$24)))) -> 94.15 | C32: =B32*Supuestos!$C$6 -> 564.9 | D32: =C32*Supuestos!$C$42 -> 2447.9 | E32: =IF(A32=0,0,MAX(Supuestos!$C$23,ROUNDUP(C32/Supuestos!$C$18,0))) -> 19 | F32: =MAX(0,E32-IF(A31=0,Supuestos!$C$23,E31))+Supuestos!$C$19*E32 -> 0.57 | G32: =IF(A32=0,0,MAX(1,ROUNDUP(B32/Supuestos!$C$21,0))) -> 2 | H32: =D32*(Supuestos!$C$14+Supuestos!$C$7) -> 195832 | I32: =D32*Supuestos!$C$43 -> 182368.55 | J32: =IF(A32=0,0,Supuestos!$C$44+G32*Supuestos!$C$26) -> 97300 | K32: =F32*Supuestos!$C$20 -> 1995 | L32: =IF(A32=0,Supuestos!$C$45,0) -> 0 | M32: =IF(A32=0,-L32,H32-I32-J32-K32) -> -85831.55 | N32: =N31+M32 -> -2159817.8 | O32: =1/(1+Supuestos!$C$46)^A32 -> 0.81342188 | P32: =M32*O32 -> -69817.261 | Q32: =Q31+P32 -> -1959928 | R32: =IF(AND(A32>0,N32>=0),1,0) -> 0 | S32: =IF(AND(A32>0,Q32>=0),1,0) -> 0
A33: 27 | B33: =IF(A33=0,0,IF(A33<=Supuestos!$C$24,Supuestos!$C$22,IF(A33>=Supuestos!$C$8,$V$7,Supuestos!$C$22+($V$7-Supuestos!$C$22)*(A33-Supuestos!$C$24)/(Supuestos!$C$8-Supuestos!$C$24)))) -> 94.15 | C33: =B33*Supuestos!$C$6 -> 564.9 | D33: =C33*Supuestos!$C$42 -> 2447.9 | E33: =IF(A33=0,0,MAX(Supuestos!$C$23,ROUNDUP(C33/Supuestos!$C$18,0))) -> 19 | F33: =MAX(0,E33-IF(A32=0,Supuestos!$C$23,E32))+Supuestos!$C$19*E33 -> 0.57 | G33: =IF(A33=0,0,MAX(1,ROUNDUP(B33/Supuestos!$C$21,0))) -> 2 | H33: =D33*(Supuestos!$C$14+Supuestos!$C$7) -> 195832 | I33: =D33*Supuestos!$C$43 -> 182368.55 | J33: =IF(A33=0,0,Supuestos!$C$44+G33*Supuestos!$C$26) -> 97300 | K33: =F33*Supuestos!$C$20 -> 1995 | L33: =IF(A33=0,Supuestos!$C$45,0) -> 0 | M33: =IF(A33=0,-L33,H33-I33-J33-K33) -> -85831.55 | N33: =N32+M33 -> -2245649.4 | O33: =1/(1+Supuestos!$C$46)^A33 -> 0.80698685 | P33: =M33*O33 -> -69264.932 | Q33: =Q32+P33 -> -2029193 | R33: =IF(AND(A33>0,N33>=0),1,0) -> 0 | S33: =IF(AND(A33>0,Q33>=0),1,0) -> 0
A34: 28 | B34: =IF(A34=0,0,IF(A34<=Supuestos!$C$24,Supuestos!$C$22,IF(A34>=Supuestos!$C$8,$V$7,Supuestos!$C$22+($V$7-Supuestos!$C$22)*(A34-Supuestos!$C$24)/(Supuestos!$C$8-Supuestos!$C$24)))) -> 94.15 | C34: =B34*Supuestos!$C$6 -> 564.9 | D34: =C34*Supuestos!$C$42 -> 2447.9 | E34: =IF(A34=0,0,MAX(Supuestos!$C$23,ROUNDUP(C34/Supuestos!$C$18,0))) -> 19 | F34: =MAX(0,E34-IF(A33=0,Supuestos!$C$23,E33))+Supuestos!$C$19*E34 -> 0.57 | G34: =IF(A34=0,0,MAX(1,ROUNDUP(B34/Supuestos!$C$21,0))) -> 2 | H34: =D34*(Supuestos!$C$14+Supuestos!$C$7) -> 195832 | I34: =D34*Supuestos!$C$43 -> 182368.55 | J34: =IF(A34=0,0,Supuestos!$C$44+G34*Supuestos!$C$26) -> 97300 | K34: =F34*Supuestos!$C$20 -> 1995 | L34: =IF(A34=0,Supuestos!$C$45,0) -> 0 | M34: =IF(A34=0,-L34,H34-I34-J34-K34) -> -85831.55 | N34: =N33+M34 -> -2331480.9 | O34: =1/(1+Supuestos!$C$46)^A34 -> 0.80060273 | P34: =M34*O34 -> -68716.973 | Q34: =Q33+P34 -> -2097910 | R34: =IF(AND(A34>0,N34>=0),1,0) -> 0 | S34: =IF(AND(A34>0,Q34>=0),1,0) -> 0
A35: 29 | B35: =IF(A35=0,0,IF(A35<=Supuestos!$C$24,Supuestos!$C$22,IF(A35>=Supuestos!$C$8,$V$7,Supuestos!$C$22+($V$7-Supuestos!$C$22)*(A35-Supuestos!$C$24)/(Supuestos!$C$8-Supuestos!$C$24)))) -> 94.15 | C35: =B35*Supuestos!$C$6 -> 564.9 | D35: =C35*Supuestos!$C$42 -> 2447.9 | E35: =IF(A35=0,0,MAX(Supuestos!$C$23,ROUNDUP(C35/Supuestos!$C$18,0))) -> 19 | F35: =MAX(0,E35-IF(A34=0,Supuestos!$C$23,E34))+Supuestos!$C$19*E35 -> 0.57 | G35: =IF(A35=0,0,MAX(1,ROUNDUP(B35/Supuestos!$C$21,0))) -> 2 | H35: =D35*(Supuestos!$C$14+Supuestos!$C$7) -> 195832 | I35: =D35*Supuestos!$C$43 -> 182368.55 | J35: =IF(A35=0,0,Supuestos!$C$44+G35*Supuestos!$C$26) -> 97300 | K35: =F35*Supuestos!$C$20 -> 1995 | L35: =IF(A35=0,Supuestos!$C$45,0) -> 0 | M35: =IF(A35=0,-L35,H35-I35-J35-K35) -> -85831.55 | N35: =N34+M35 -> -2417312.5 | O35: =1/(1+Supuestos!$C$46)^A35 -> 0.79426912 | P35: =M35*O35 -> -68173.35 | Q35: =Q34+P35 -> -2166083.3 | R35: =IF(AND(A35>0,N35>=0),1,0) -> 0 | S35: =IF(AND(A35>0,Q35>=0),1,0) -> 0
A36: 30 | B36: =IF(A36=0,0,IF(A36<=Supuestos!$C$24,Supuestos!$C$22,IF(A36>=Supuestos!$C$8,$V$7,Supuestos!$C$22+($V$7-Supuestos!$C$22)*(A36-Supuestos!$C$24)/(Supuestos!$C$8-Supuestos!$C$24)))) -> 94.15 | C36: =B36*Supuestos!$C$6 -> 564.9 | D36: =C36*Supuestos!$C$42 -> 2447.9 | E36: =IF(A36=0,0,MAX(Supuestos!$C$23,ROUNDUP(C36/Supuestos!$C$18,0))) -> 19 | F36: =MAX(0,E36-IF(A35=0,Supuestos!$C$23,E35))+Supuestos!$C$19*E36 -> 0.57 | G36: =IF(A36=0,0,MAX(1,ROUNDUP(B36/Supuestos!$C$21,0))) -> 2 | H36: =D36*(Supuestos!$C$14+Supuestos!$C$7) -> 195832 | I36: =D36*Supuestos!$C$43 -> 182368.55 | J36: =IF(A36=0,0,Supuestos!$C$44+G36*Supuestos!$C$26) -> 97300 | K36: =F36*Supuestos!$C$20 -> 1995 | L36: =IF(A36=0,Supuestos!$C$45,0) -> 0 | M36: =IF(A36=0,-L36,H36-I36-J36-K36) -> -85831.55 | N36: =N35+M36 -> -2503144 | O36: =1/(1+Supuestos!$C$46)^A36 -> 0.78798561 | P36: =M36*O36 -> -67634.026 | Q36: =Q35+P36 -> -2233717.3 | R36: =IF(AND(A36>0,N36>=0),1,0) -> 0 | S36: =IF(AND(A36>0,Q36>=0),1,0) -> 0
A37: 31 | B37: =IF(A37=0,0,IF(A37<=Supuestos!$C$24,Supuestos!$C$22,IF(A37>=Supuestos!$C$8,$V$7,Supuestos!$C$22+($V$7-Supuestos!$C$22)*(A37-Supuestos!$C$24)/(Supuestos!$C$8-Supuestos!$C$24)))) -> 94.15 | C37: =B37*Supuestos!$C$6 -> 564.9 | D37: =C37*Supuestos!$C$42 -> 2447.9 | E37: =IF(A37=0,0,MAX(Supuestos!$C$23,ROUNDUP(C37/Supuestos!$C$18,0))) -> 19 | F37: =MAX(0,E37-IF(A36=0,Supuestos!$C$23,E36))+Supuestos!$C$19*E37 -> 0.57 | G37: =IF(A37=0,0,MAX(1,ROUNDUP(B37/Supuestos!$C$21,0))) -> 2 | H37: =D37*(Supuestos!$C$14+Supuestos!$C$7) -> 195832 | I37: =D37*Supuestos!$C$43 -> 182368.55 | J37: =IF(A37=0,0,Supuestos!$C$44+G37*Supuestos!$C$26) -> 97300 | K37: =F37*Supuestos!$C$20 -> 1995 | L37: =IF(A37=0,Supuestos!$C$45,0) -> 0 | M37: =IF(A37=0,-L37,H37-I37-J37-K37) -> -85831.55 | N37: =N36+M37 -> -2588975.6 | O37: =1/(1+Supuestos!$C$46)^A37 -> 0.78175181 | P37: =M37*O37 -> -67098.97 | Q37: =Q36+P37 -> -2300816.3 | R37: =IF(AND(A37>0,N37>=0),1,0) -> 0 | S37: =IF(AND(A37>0,Q37>=0),1,0) -> 0
A38: 32 | B38: =IF(A38=0,0,IF(A38<=Supuestos!$C$24,Supuestos!$C$22,IF(A38>=Supuestos!$C$8,$V$7,Supuestos!$C$22+($V$7-Supuestos!$C$22)*(A38-Supuestos!$C$24)/(Supuestos!$C$8-Supuestos!$C$24)))) -> 94.15 | C38: =B38*Supuestos!$C$6 -> 564.9 | D38: =C38*Supuestos!$C$42 -> 2447.9 | E38: =IF(A38=0,0,MAX(Supuestos!$C$23,ROUNDUP(C38/Supuestos!$C$18,0))) -> 19 | F38: =MAX(0,E38-IF(A37=0,Supuestos!$C$23,E37))+Supuestos!$C$19*E38 -> 0.57 | G38: =IF(A38=0,0,MAX(1,ROUNDUP(B38/Supuestos!$C$21,0))) -> 2 | H38: =D38*(Supuestos!$C$14+Supuestos!$C$7) -> 195832 | I38: =D38*Supuestos!$C$43 -> 182368.55 | J38: =IF(A38=0,0,Supuestos!$C$44+G38*Supuestos!$C$26) -> 97300 | K38: =F38*Supuestos!$C$20 -> 1995 | L38: =IF(A38=0,Supuestos!$C$45,0) -> 0 | M38: =IF(A38=0,-L38,H38-I38-J38-K38) -> -85831.55 | N38: =N37+M38 -> -2674807.1 | O38: =1/(1+Supuestos!$C$46)^A38 -> 0.77556733 | P38: =M38*O38 -> -66568.146 | Q38: =Q37+P38 -> -2367384.4 | R38: =IF(AND(A38>0,N38>=0),1,0) -> 0 | S38: =IF(AND(A38>0,Q38>=0),1,0) -> 0
A39: 33 | B39: =IF(A39=0,0,IF(A39<=Supuestos!$C$24,Supuestos!$C$22,IF(A39>=Supuestos!$C$8,$V$7,Supuestos!$C$22+($V$7-Supuestos!$C$22)*(A39-Supuestos!$C$24)/(Supuestos!$C$8-Supuestos!$C$24)))) -> 94.15 | C39: =B39*Supuestos!$C$6 -> 564.9 | D39: =C39*Supuestos!$C$42 -> 2447.9 | E39: =IF(A39=0,0,MAX(Supuestos!$C$23,ROUNDUP(C39/Supuestos!$C$18,0))) -> 19 | F39: =MAX(0,E39-IF(A38=0,Supuestos!$C$23,E38))+Supuestos!$C$19*E39 -> 0.57 | G39: =IF(A39=0,0,MAX(1,ROUNDUP(B39/Supuestos!$C$21,0))) -> 2 | H39: =D39*(Supuestos!$C$14+Supuestos!$C$7) -> 195832 | I39: =D39*Supuestos!$C$43 -> 182368.55 | J39: =IF(A39=0,0,Supuestos!$C$44+G39*Supuestos!$C$26) -> 97300 | K39: =F39*Supuestos!$C$20 -> 1995 | L39: =IF(A39=0,Supuestos!$C$45,0) -> 0 | M39: =IF(A39=0,-L39,H39-I39-J39-K39) -> -85831.55 | N39: =N38+M39 -> -2760638.7 | O39: =1/(1+Supuestos!$C$46)^A39 -> 0.76943177 | P39: =M39*O39 -> -66041.522 | Q39: =Q38+P39 -> -2433426 | R39: =IF(AND(A39>0,N39>=0),1,0) -> 0 | S39: =IF(AND(A39>0,Q39>=0),1,0) -> 0
A40: 34 | B40: =IF(A40=0,0,IF(A40<=Supuestos!$C$24,Supuestos!$C$22,IF(A40>=Supuestos!$C$8,$V$7,Supuestos!$C$22+($V$7-Supuestos!$C$22)*(A40-Supuestos!$C$24)/(Supuestos!$C$8-Supuestos!$C$24)))) -> 94.15 | C40: =B40*Supuestos!$C$6 -> 564.9 | D40: =C40*Supuestos!$C$42 -> 2447.9 | E40: =IF(A40=0,0,MAX(Supuestos!$C$23,ROUNDUP(C40/Supuestos!$C$18,0))) -> 19 | F40: =MAX(0,E40-IF(A39=0,Supuestos!$C$23,E39))+Supuestos!$C$19*E40 -> 0.57 | G40: =IF(A40=0,0,MAX(1,ROUNDUP(B40/Supuestos!$C$21,0))) -> 2 | H40: =D40*(Supuestos!$C$14+Supuestos!$C$7) -> 195832 | I40: =D40*Supuestos!$C$43 -> 182368.55 | J40: =IF(A40=0,0,Supuestos!$C$44+G40*Supuestos!$C$26) -> 97300 | K40: =F40*Supuestos!$C$20 -> 1995 | L40: =IF(A40=0,Supuestos!$C$45,0) -> 0 | M40: =IF(A40=0,-L40,H40-I40-J40-K40) -> -85831.55 | N40: =N39+M40 -> -2846470.2 | O40: =1/(1+Supuestos!$C$46)^A40 -> 0.76334475 | P40: =M40*O40 -> -65519.063 | Q40: =Q39+P40 -> -2498945 | R40: =IF(AND(A40>0,N40>=0),1,0) -> 0 | S40: =IF(AND(A40>0,Q40>=0),1,0) -> 0
...

Sheet Flujo Realista
A1: Flujo mensual — escenario realista (pesos de 2026)
A2: Todas las celdas son fórmulas que leen la hoja «Supuestos» (texto verde: vínculo). Mes 0 = inversión inicial.
U3: Indicador | V3: Valor
U4: Escenario | V4: Realista
A5: Mes | B5: Familias | C5: Horas por semana | D5: Horas al mes | E5: Cuidadoras | F5: Cuidadoras nuevas (incluye rotación) | G5: Trabajadoras sociales | H5: Ingresos ($) | I5: Costo variable ($) | J5: Costos fijos ($) | K5: Capacitación ($) | L5: Inversión ($) | M5: Flujo neto ($) | N5: Flujo acumulado ($) | O5: Factor de descuento | P5: Flujo descontado ($) | Q5: Acumulado descontado ($) | R5: ¿Recuperado? | S5: ¿Recuperado (descontado)? | U5: Tarifa por hora (copago + subsidio) | V5: =Supuestos!$C$14+Supuestos!$D$7 -> 100
A6: 0 | B6: =IF(A6=0,0,IF(A6<=Supuestos!$C$24,Supuestos!$C$22,IF(A6>=Supuestos!$D$8,$V$7,Supuestos!$C$22+($V$7-Supuestos!$C$22)*(A6-Supuestos!$C$24)/(Supuestos!$D$8-Supuestos!$C$24)))) -> 0 | C6: =B6*Supuestos!$D$6 -> 0 | D6: =C6*Supuestos!$C$42 -> 0 | E6: =IF(A6=0,0,MAX(Supuestos!$C$23,ROUNDUP(C6/Supuestos!$C$18,0))) -> 0 | F6: 0 | G6: =IF(A6=0,0,MAX(1,ROUNDUP(B6/Supuestos!$C$21,0))) -> 0 | H6: =D6*(Supuestos!$C$14+Supuestos!$D$7) -> 0 | I6: =D6*Supuestos!$C$43 -> 0 | J6: =IF(A6=0,0,Supuestos!$C$44+G6*Supuestos!$C$26) -> 0 | K6: =F6*Supuestos!$C$20 -> 0 | L6: =IF(A6=0,Supuestos!$C$45,0) -> 226000 | M6: =IF(A6=0,-L6,H6-I6-J6-K6) -> -226000 | N6: =M6 -> -226000 | O6: =1/(1+Supuestos!$C$46)^A6 -> 1 | P6: =M6*O6 -> -226000 | Q6: =P6 -> -226000 | R6: =IF(AND(A6>0,N6>=0),1,0) -> 0 | S6: =IF(AND(A6>0,Q6>=0),1,0) -> 0 | U6: Margen por hora | V6: =V5-Supuestos!$C$43 -> 25.5
A7: 1 | B7: =IF(A7=0,0,IF(A7<=Supuestos!$C$24,Supuestos!$C$22,IF(A7>=Supuestos!$D$8,$V$7,Supuestos!$C$22+($V$7-Supuestos!$C$22)*(A7-Supuestos!$C$24)/(Supuestos!$D$8-Supuestos!$C$24)))) -> 15 | C7: =B7*Supuestos!$D$6 -> 120 | D7: =C7*Supuestos!$C$42 -> 520 | E7: =IF(A7=0,0,MAX(Supuestos!$C$23,ROUNDUP(C7/Supuestos!$C$18,0))) -> 6 | F7: =MAX(0,E7-IF(A6=0,Supuestos!$C$23,E6))+Supuestos!$C$19*E7 -> 0.18 | G7: =IF(A7=0,0,MAX(1,ROUNDUP(B7/Supuestos!$C$21,0))) -> 1 | H7: =D7*(Supuestos!$C$14+Supuestos!$D$7) -> 52000 | I7: =D7*Supuestos!$C$43 -> 38740 | J7: =IF(A7=0,0,Supuestos!$C$44+G7*Supuestos!$C$26) -> 73000 | K7: =F7*Supuestos!$C$20 -> 630 | L7: =IF(A7=0,Supuestos!$C$45,0) -> 0 | M7: =IF(A7=0,-L7,H7-I7-J7-K7) -> -60370 | N7: =N6+M7 -> -286370 | O7: =1/(1+Supuestos!$C$46)^A7 -> 0.99208894 | P7: =M7*O7 -> -59892.41 | Q7: =Q6+P7 -> -285892.41 | R7: =IF(AND(A7>0,N7>=0),1,0) -> 0 | S7: =IF(AND(A7>0,Q7>=0),1,0) -> 0 | U7: Familias objetivo (estado estable) | V7: =MAX(Supuestos!$C$13*Supuestos!$D$5,Supuestos!$C$22) -> 188.3
A8: 2 | B8: =IF(A8=0,0,IF(A8<=Supuestos!$C$24,Supuestos!$C$22,IF(A8>=Supuestos!$D$8,$V$7,Supuestos!$C$22+($V$7-Supuestos!$C$22)*(A8-Supuestos!$C$24)/(Supuestos!$D$8-Supuestos!$C$24)))) -> 15 | C8: =B8*Supuestos!$D$6 -> 120 | D8: =C8*Supuestos!$C$42 -> 520 | E8: =IF(A8=0,0,MAX(Supuestos!$C$23,ROUNDUP(C8/Supuestos!$C$18,0))) -> 6 | F8: =MAX(0,E8-IF(A7=0,Supuestos!$C$23,E7))+Supuestos!$C$19*E8 -> 0.18 | G8: =IF(A8=0,0,MAX(1,ROUNDUP(B8/Supuestos!$C$21,0))) -> 1 | H8: =D8*(Supuestos!$C$14+Supuestos!$D$7) -> 52000 | I8: =D8*Supuestos!$C$43 -> 38740 | J8: =IF(A8=0,0,Supuestos!$C$44+G8*Supuestos!$C$26) -> 73000 | K8: =F8*Supuestos!$C$20 -> 630 | L8: =IF(A8=0,Supuestos!$C$45,0) -> 0 | M8: =IF(A8=0,-L8,H8-I8-J8-K8) -> -60370 | N8: =N7+M8 -> -346740 | O8: =1/(1+Supuestos!$C$46)^A8 -> 0.98424047 | P8: =M8*O8 -> -59418.597 | Q8: =Q7+P8 -> -345311.01 | R8: =IF(AND(A8>0,N8>=0),1,0) -> 0 | S8: =IF(AND(A8>0,Q8>=0),1,0) -> 0 | U8: VAN a la tasa de descuento | V8: =SUM(P6:P66) -> 487908
A9: 3 | B9: =IF(A9=0,0,IF(A9<=Supuestos!$C$24,Supuestos!$C$22,IF(A9>=Supuestos!$D$8,$V$7,Supuestos!$C$22+($V$7-Supuestos!$C$22)*(A9-Supuestos!$C$24)/(Supuestos!$D$8-Supuestos!$C$24)))) -> 15 | C9: =B9*Supuestos!$D$6 -> 120 | D9: =C9*Supuestos!$C$42 -> 520 | E9: =IF(A9=0,0,MAX(Supuestos!$C$23,ROUNDUP(C9/Supuestos!$C$18,0))) -> 6 | F9: =MAX(0,E9-IF(A8=0,Supuestos!$C$23,E8))+Supuestos!$C$19*E9 -> 0.18 | G9: =IF(A9=0,0,MAX(1,ROUNDUP(B9/Supuestos!$C$21,0))) -> 1 | H9: =D9*(Supuestos!$C$14+Supuestos!$D$7) -> 52000 | I9: =D9*Supuestos!$C$43 -> 38740 | J9: =IF(A9=0,0,Supuestos!$C$44+G9*Supuestos!$C$26) -> 73000 | K9: =F9*Supuestos!$C$20 -> 630 | L9: =IF(A9=0,Supuestos!$C$45,0) -> 0 | M9: =IF(A9=0,-L9,H9-I9-J9-K9) -> -60370 | N9: =N8+M9 -> -407110 | O9: =1/(1+Supuestos!$C$46)^A9 -> 0.97645409 | P9: =M9*O9 -> -58948.533 | Q9: =Q8+P9 -> -404259.54 | R9: =IF(AND(A9>0,N9>=0),1,0) -> 0 | S9: =IF(AND(A9>0,Q9>=0),1,0) -> 0 | U9: TIR mensual | V9: =IFERROR(IRR(M6:M66,0.02),"No existe") -> 0.023098352
A10: 4 | B10: =IF(A10=0,0,IF(A10<=Supuestos!$C$24,Supuestos!$C$22,IF(A10>=Supuestos!$D$8,$V$7,Supuestos!$C$22+($V$7-Supuestos!$C$22)*(A10-Supuestos!$C$24)/(Supuestos!$D$8-Supuestos!$C$24)))) -> 15 | C10: =B10*Supuestos!$D$6 -> 120 | D10: =C10*Supuestos!$C$42 -> 520 | E10: =IF(A10=0,0,MAX(Supuestos!$C$23,ROUNDUP(C10/Supuestos!$C$18,0))) -> 6 | F10: =MAX(0,E10-IF(A9=0,Supuestos!$C$23,E9))+Supuestos!$C$19*E10 -> 0.18 | G10: =IF(A10=0,0,MAX(1,ROUNDUP(B10/Supuestos!$C$21,0))) -> 1 | H10: =D10*(Supuestos!$C$14+Supuestos!$D$7) -> 52000 | I10: =D10*Supuestos!$C$43 -> 38740 | J10: =IF(A10=0,0,Supuestos!$C$44+G10*Supuestos!$C$26) -> 73000 | K10: =F10*Supuestos!$C$20 -> 630 | L10: =IF(A10=0,Supuestos!$C$45,0) -> 0 | M10: =IF(A10=0,-L10,H10-I10-J10-K10) -> -60370 | N10: =N9+M10 -> -467480 | O10: =1/(1+Supuestos!$C$46)^A10 -> 0.96872931 | P10: =M10*O10 -> -58482.188 | Q10: =Q9+P10 -> -462741.73 | R10: =IF(AND(A10>0,N10>=0),1,0) -> 0 | S10: =IF(AND(A10>0,Q10>=0),1,0) -> 0 | U10: TIR anual equivalente | V10: =IFERROR((1+V9)^12-1,"No existe") -> 0.31525095
A11: 5 | B11: =IF(A11=0,0,IF(A11<=Supuestos!$C$24,Supuestos!$C$22,IF(A11>=Supuestos!$D$8,$V$7,Supuestos!$C$22+($V$7-Supuestos!$C$22)*(A11-Supuestos!$C$24)/(Supuestos!$D$8-Supuestos!$C$24)))) -> 15 | C11: =B11*Supuestos!$D$6 -> 120 | D11: =C11*Supuestos!$C$42 -> 520 | E11: =IF(A11=0,0,MAX(Supuestos!$C$23,ROUNDUP(C11/Supuestos!$C$18,0))) -> 6 | F11: =MAX(0,E11-IF(A10=0,Supuestos!$C$23,E10))+Supuestos!$C$19*E11 -> 0.18 | G11: =IF(A11=0,0,MAX(1,ROUNDUP(B11/Supuestos!$C$21,0))) -> 1 | H11: =D11*(Supuestos!$C$14+Supuestos!$D$7) -> 52000 | I11: =D11*Supuestos!$C$43 -> 38740 | J11: =IF(A11=0,0,Supuestos!$C$44+G11*Supuestos!$C$26) -> 73000 | K11: =F11*Supuestos!$C$20 -> 630 | L11: =IF(A11=0,Supuestos!$C$45,0) -> 0 | M11: =IF(A11=0,-L11,H11-I11-J11-K11) -> -60370 | N11: =N10+M11 -> -527850 | O11: =1/(1+Supuestos!$C$46)^A11 -> 0.96106563 | P11: =M11*O11 -> -58019.532 | Q11: =Q10+P11 -> -520761.26 | R11: =IF(AND(A11>0,N11>=0),1,0) -> 0 | S11: =IF(AND(A11>0,Q11>=0),1,0) -> 0 | U11: Payback (meses) | V11: =IFERROR(INDEX(A6:A66,MATCH(1,R6:R66,0)),"No se recupera") -> 37
A12: 6 | B12: =IF(A12=0,0,IF(A12<=Supuestos!$C$24,Supuestos!$C$22,IF(A12>=Supuestos!$D$8,$V$7,Supuestos!$C$22+($V$7-Supuestos!$C$22)*(A12-Supuestos!$C$24)/(Supuestos!$D$8-Supuestos!$C$24)))) -> 15 | C12: =B12*Supuestos!$D$6 -> 120 | D12: =C12*Supuestos!$C$42 -> 520 | E12: =IF(A12=0,0,MAX(Supuestos!$C$23,ROUNDUP(C12/Supuestos!$C$18,0))) -> 6 | F12: =MAX(0,E12-IF(A11=0,Supuestos!$C$23,E11))+Supuestos!$C$19*E12 -> 0.18 | G12: =IF(A12=0,0,MAX(1,ROUNDUP(B12/Supuestos!$C$21,0))) -> 1 | H12: =D12*(Supuestos!$C$14+Supuestos!$D$7) -> 52000 | I12: =D12*Supuestos!$C$43 -> 38740 | J12: =IF(A12=0,0,Supuestos!$C$44+G12*Supuestos!$C$26) -> 73000 | K12: =F12*Supuestos!$C$20 -> 630 | L12: =IF(A12=0,Supuestos!$C$45,0) -> 0 | M12: =IF(A12=0,-L12,H12-I12-J12-K12) -> -60370 | N12: =N11+M12 -> -588220 | O12: =1/(1+Supuestos!$C$46)^A12 -> 0.95346259 | P12: =M12*O12 -> -57560.537 | Q12: =Q11+P12 -> -578321.8 | R12: =IF(AND(A12>0,N12>=0),1,0) -> 0 | S12: =IF(AND(A12>0,Q12>=0),1,0) -> 0 | U12: Payback descontado (meses) | V12: =IFERROR(INDEX(A6:A66,MATCH(1,S6:S66,0)),"No se recupera") -> 42
A13: 7 | B13: =IF(A13=0,0,IF(A13<=Supuestos!$C$24,Supuestos!$C$22,IF(A13>=Supuestos!$D$8,$V$7,Supuestos!$C$22+($V$7-Supuestos!$C$22)*(A13-Supuestos!$C$24)/(Supuestos!$D$8-Supuestos!$C$24)))) -> 29.441667 | C13: =B13*Supuestos!$D$6 -> 235.53333 | D13: =C13*Supuestos!$C$42 -> 1020.6444 | E13: =IF(A13=0,0,MAX(Supuestos!$C$23,ROUNDUP(C13/Supuestos!$C$18,0))) -> 8 | F13: =MAX(0,E13-IF(A12=0,Supuestos!$C$23,E12))+Supuestos!$C$19*E13 -> 2.24 | G13: =IF(A13=0,0,MAX(1,ROUNDUP(B13/Supuestos!$C$21,0))) -> 1 | H13: =D13*(Supuestos!$C$14+Supuestos!$D$7) -> 102064.44 | I13: =D13*Supuestos!$C$43 -> 76038.011 | J13: =IF(A13=0,0,Supuestos!$C$44+G13*Supuestos!$C$26) -> 73000 | K13: =F13*Supuestos!$C$20 -> 7840 | L13: =IF(A13=0,Supuestos!$C$45,0) -> 0 | M13: =IF(A13=0,-L13,H13-I13-J13-K13) -> -54813.567 | N13: =N12+M13 -> -643033.57 | O13: =1/(1+Supuestos!$C$46)^A13 -> 0.94591969 | P13: =M13*O13 -> -51849.232 | Q13: =Q12+P13 -> -630171.03 | R13: =IF(AND(A13>0,N13>=0),1,0) -> 0 | S13: =IF(AND(A13>0,Q13>=0),1,0) -> 0 | U13: Costos fijos en estado estable | V13: =J66 -> 121600
A14: 8 | B14: =IF(A14=0,0,IF(A14<=Supuestos!$C$24,Supuestos!$C$22,IF(A14>=Supuestos!$D$8,$V$7,Supuestos!$C$22+($V$7-Supuestos!$C$22)*(A14-Supuestos!$C$24)/(Supuestos!$D$8-Supuestos!$C$24)))) -> 43.883333 | C14: =B14*Supuestos!$D$6 -> 351.06667 | D14: =C14*Supuestos!$C$42 -> 1521.2889 | E14: =IF(A14=0,0,MAX(Supuestos!$C$23,ROUNDUP(C14/Supuestos!$C$18,0))) -> 12 | F14: =MAX(0,E14-IF(A13=0,Supuestos!$C$23,E13))+Supuestos!$C$19*E14 -> 4.36 | G14: =IF(A14=0,0,MAX(1,ROUNDUP(B14/Supuestos!$C$21,0))) -> 1 | H14: =D14*(Supuestos!$C$14+Supuestos!$D$7) -> 152128.89 | I14: =D14*Supuestos!$C$43 -> 113336.02 | J14: =IF(A14=0,0,Supuestos!$C$44+G14*Supuestos!$C$26) -> 73000 | K14: =F14*Supuestos!$C$20 -> 15260 | L14: =IF(A14=0,Supuestos!$C$45,0) -> 0 | M14: =IF(A14=0,-L14,H14-I14-J14-K14) -> -49467.133 | N14: =N13+M14 -> -692500.7 | O14: =1/(1+Supuestos!$C$46)^A14 -> 0.93843647 | P14: =M14*O14 -> -46421.762 | Q14: =Q13+P14 -> -676592.79 | R14: =IF(AND(A14>0,N14>=0),1,0) -> 0 | S14: =IF(AND(A14>0,Q14>=0),1,0) -> 0 | U14: Punto de equilibrio (horas al mes) | V14: =IF(V6>0,V13/V6,"No existe") -> 4768.6275
A15: 9 | B15: =IF(A15=0,0,IF(A15<=Supuestos!$C$24,Supuestos!$C$22,IF(A15>=Supuestos!$D$8,$V$7,Supuestos!$C$22+($V$7-Supuestos!$C$22)*(A15-Supuestos!$C$24)/(Supuestos!$D$8-Supuestos!$C$24)))) -> 58.325 | C15: =B15*Supuestos!$D$6 -> 466.6 | D15: =C15*Supuestos!$C$42 -> 2021.9333 | E15: =IF(A15=0,0,MAX(Supuestos!$C$23,ROUNDUP(C15/Supuestos!$C$18,0))) -> 16 | F15: =MAX(0,E15-IF(A14=0,Supuestos!$C$23,E14))+Supuestos!$C$19*E15 -> 4.48 | G15: =IF(A15=0,0,MAX(1,ROUNDUP(B15/Supuestos!$C$21,0))) -> 1 | H15: =D15*(Supuestos!$C$14+Supuestos!$D$7) -> 202193.33 | I15: =D15*Supuestos!$C$43 -> 150634.03 | J15: =IF(A15=0,0,Supuestos!$C$44+G15*Supuestos!$C$26) -> 73000 | K15: =F15*Supuestos!$C$20 -> 15680 | L15: =IF(A15=0,Supuestos!$C$45,0) -> 0 | M15: =IF(A15=0,-L15,H15-I15-J15-K15) -> -37120.7 | N15: =N14+M15 -> -729621.4 | O15: =1/(1+Supuestos!$C$46)^A15 -> 0.93101244 | P15: =M15*O15 -> -34559.834 | Q15: =Q14+P15 -> -711152.62 | R15: =IF(AND(A15>0,N15>=0),1,0) -> 0 | S15: =IF(AND(A15>0,Q15>=0),1,0) -> 0 | U15: Punto de equilibrio (familias) | V15: =IF(V6>0,V14/Supuestos!$C$42/Supuestos!$D$6,"No existe") -> 137.55656
A16: 10 | B16: =IF(A16=0,0,IF(A16<=Supuestos!$C$24,Supuestos!$C$22,IF(A16>=Supuestos!$D$8,$V$7,Supuestos!$C$22+($V$7-Supuestos!$C$22)*(A16-Supuestos!$C$24)/(Supuestos!$D$8-Supuestos!$C$24)))) -> 72.766667 | C16: =B16*Supuestos!$D$6 -> 582.13333 | D16: =C16*Supuestos!$C$42 -> 2522.5778 | E16: =IF(A16=0,0,MAX(Supuestos!$C$23,ROUNDUP(C16/Supuestos!$C$18,0))) -> 20 | F16: =MAX(0,E16-IF(A15=0,Supuestos!$C$23,E15))+Supuestos!$C$19*E16 -> 4.6 | G16: =IF(A16=0,0,MAX(1,ROUNDUP(B16/Supuestos!$C$21,0))) -> 1 | H16: =D16*(Supuestos!$C$14+Supuestos!$D$7) -> 252257.78 | I16: =D16*Supuestos!$C$43 -> 187932.04 | J16: =IF(A16=0,0,Supuestos!$C$44+G16*Supuestos!$C$26) -> 73000 | K16: =F16*Supuestos!$C$20 -> 16100 | L16: =IF(A16=0,Supuestos!$C$45,0) -> 0 | M16: =IF(A16=0,-L16,H16-I16-J16-K16) -> -24774.267 | N16: =N15+M16 -> -754395.67 | O16: =1/(1+Supuestos!$C$46)^A16 -> 0.92364715 | P16: =M16*O16 -> -22882.681 | Q16: =Q15+P16 -> -734035.31 | R16: =IF(AND(A16>0,N16>=0),1,0) -> 0 | S16: =IF(AND(A16>0,Q16>=0),1,0) -> 0 | U16: Utilidad neta acumulada (60 meses) | V16: =N66 -> 912104.2
A17: 11 | B17: =IF(A17=0,0,IF(A17<=Supuestos!$C$24,Supuestos!$C$22,IF(A17>=Supuestos!$D$8,$V$7,Supuestos!$C$22+($V$7-Supuestos!$C$22)*(A17-Supuestos!$C$24)/(Supuestos!$D$8-Supuestos!$C$24)))) -> 87.208333 | C17: =B17*Supuestos!$D$6 -> 697.66667 | D17: =C17*Supuestos!$C$42 -> 3023.2222 | E17: =IF(A17=0,0,MAX(Supuestos!$C$23,ROUNDUP(C17/Supuestos!$C$18,0))) -> 24 | F17: =MAX(0,E17-IF(A16=0,Supuestos!$C$23,E16))+Supuestos!$C$19*E17 -> 4.72 | G17: =IF(A17=0,0,MAX(1,ROUNDUP(B17/Supuestos!$C$21,0))) -> 2 | H17: =D17*(Supuestos!$C$14+Supuestos!$D$7) -> 302322.22 | I17: =D17*Supuestos!$C$43 -> 225230.06 | J17: =IF(A17=0,0,Supuestos!$C$44+G17*Supuestos!$C$26) -> 97300 | K17: =F17*Supuestos!$C$20 -> 16520 | L17: =IF(A17=0,Supuestos!$C$45,0) -> 0 | M17: =IF(A17=0,-L17,H17-I17-J17-K17) -> -36727.833 | N17: =N16+M17 -> -791123.5 | O17: =1/(1+Supuestos!$C$46)^A17 -> 0.91634013 | P17: =M17*O17 -> -33655.187 | Q17: =Q16+P17 -> -767690.49 | R17: =IF(AND(A17>0,N17>=0),1,0) -> 0 | S17: =IF(AND(A17>0,Q17>=0),1,0) -> 0 | U17: Inversión inicial | V17: =L6 -> 226000
A18: 12 | B18: =IF(A18=0,0,IF(A18<=Supuestos!$C$24,Supuestos!$C$22,IF(A18>=Supuestos!$D$8,$V$7,Supuestos!$C$22+($V$7-Supuestos!$C$22)*(A18-Supuestos!$C$24)/(Supuestos!$D$8-Supuestos!$C$24)))) -> 101.65 | C18: =B18*Supuestos!$D$6 -> 813.2 | D18: =C18*Supuestos!$C$42 -> 3523.8667 | E18: =IF(A18=0,0,MAX(Supuestos!$C$23,ROUNDUP(C18/Supuestos!$C$18,0))) -> 28 | F18: =MAX(0,E18-IF(A17=0,Supuestos!$C$23,E17))+Supuestos!$C$19*E18 -> 4.84 | G18: =IF(A18=0,0,MAX(1,ROUNDUP(B18/Supuestos!$C$21,0))) -> 2 | H18: =D18*(Supuestos!$C$14+Supuestos!$D$7) -> 352386.67 | I18: =D18*Supuestos!$C$43 -> 262528.07 | J18: =IF(A18=0,0,Supuestos!$C$44+G18*Supuestos!$C$26) -> 97300 | K18: =F18*Supuestos!$C$20 -> 16940 | L18: =IF(A18=0,Supuestos!$C$45,0) -> 0 | M18: =IF(A18=0,-L18,H18-I18-J18-K18) -> -24381.4 | N18: =N17+M18 -> -815504.9 | O18: =1/(1+Supuestos!$C$46)^A18 -> 0.90909091 | P18: =M18*O18 -> -22164.909 | Q18: =Q17+P18 -> -789855.4 | R18: =IF(AND(A18>0,N18>=0),1,0) -> 0 | S18: =IF(AND(A18>0,Q18>=0),1,0) -> 0 | U18: Capital de operación (3 meses) | V18: =3*(J7+I7) -> 335220
A19: 13 | B19: =IF(A19=0,0,IF(A19<=Supuestos!$C$24,Supuestos!$C$22,IF(A19>=Supuestos!$D$8,$V$7,Supuestos!$C$22+($V$7-Supuestos!$C$22)*(A19-Supuestos!$C$24)/(Supuestos!$D$8-Supuestos!$C$24)))) -> 116.09167 | C19: =B19*Supuestos!$D$6 -> 928.73333 | D19: =C19*Supuestos!$C$42 -> 4024.5111 | E19: =IF(A19=0,0,MAX(Supuestos!$C$23,ROUNDUP(C19/Supuestos!$C$18,0))) -> 31 | F19: =MAX(0,E19-IF(A18=0,Supuestos!$C$23,E18))+Supuestos!$C$19*E19 -> 3.93 | G19: =IF(A19=0,0,MAX(1,ROUNDUP(B19/Supuestos!$C$21,0))) -> 2 | H19: =D19*(Supuestos!$C$14+Supuestos!$D$7) -> 402451.11 | I19: =D19*Supuestos!$C$43 -> 299826.08 | J19: =IF(A19=0,0,Supuestos!$C$44+G19*Supuestos!$C$26) -> 97300 | K19: =F19*Supuestos!$C$20 -> 13755 | L19: =IF(A19=0,Supuestos!$C$45,0) -> 0 | M19: =IF(A19=0,-L19,H19-I19-J19-K19) -> -8429.9667 | N19: =N18+M19 -> -823934.87 | O19: =1/(1+Supuestos!$C$46)^A19 -> 0.90189904 | P19: =M19*O19 -> -7602.9788 | Q19: =Q18+P19 -> -797458.38 | R19: =IF(AND(A19>0,N19>=0),1,0) -> 0 | S19: =IF(AND(A19>0,Q19>=0),1,0) -> 0 | U19: Colchón para imprevistos | V19: =Supuestos!$C$36*(V17+V18) -> 56122
A20: 14 | B20: =IF(A20=0,0,IF(A20<=Supuestos!$C$24,Supuestos!$C$22,IF(A20>=Supuestos!$D$8,$V$7,Supuestos!$C$22+($V$7-Supuestos!$C$22)*(A20-Supuestos!$C$24)/(Supuestos!$D$8-Supuestos!$C$24)))) -> 130.53333 | C20: =B20*Supuestos!$D$6 -> 1044.2667 | D20: =C20*Supuestos!$C$42 -> 4525.1556 | E20: =IF(A20=0,0,MAX(Supuestos!$C$23,ROUNDUP(C20/Supuestos!$C$18,0))) -> 35 | F20: =MAX(0,E20-IF(A19=0,Supuestos!$C$23,E19))+Supuestos!$C$19*E20 -> 5.05 | G20: =IF(A20=0,0,MAX(1,ROUNDUP(B20/Supuestos!$C$21,0))) -> 2 | H20: =D20*(Supuestos!$C$14+Supuestos!$D$7) -> 452515.56 | I20: =D20*Supuestos!$C$43 -> 337124.09 | J20: =IF(A20=0,0,Supuestos!$C$44+G20*Supuestos!$C$26) -> 97300 | K20: =F20*Supuestos!$C$20 -> 17675 | L20: =IF(A20=0,Supuestos!$C$45,0) -> 0 | M20: =IF(A20=0,-L20,H20-I20-J20-K20) -> 416.46667 | N20: =N19+M20 -> -823518.4 | O20: =1/(1+Supuestos!$C$46)^A20 -> 0.89476407 | P20: =M20*O20 -> 372.63941 | Q20: =Q19+P20 -> -797085.74 | R20: =IF(AND(A20>0,N20>=0),1,0) -> 0 | S20: =IF(AND(A20>0,Q20>=0),1,0) -> 0 | U20: Requerimiento total de capital | V20: =V17+V18+V19 -> 617342
